<?xml version="1.0" ?>
<!-- =================================================================================== -->
<!-- |    This document was autogenerated by xacro from models/navvis.xacro            | -->
<!-- |    EDITING THIS FILE BY HAND IS NOT RECOMMENDED                                 | -->
<!-- =================================================================================== -->
<robot name="Navvis" xmlns:xacro="https://www.ros.org/wiki/xacro">
  <material name="white">
    <color rgba="1 1 1 1"/>
  </material>
  <material name="black">
    <color rgba="0 0 0 1"/>
  </material>
  <link name="base">
    <visual>
      <material name="white"/>
      <origin xyz=".2 0 .99"/>
      <geometry>
        <box size="0.2 0.3 1.80"/>
      </geometry>
    </visual>
    <collision>
      <geometry>
        <box size="0.94 0.78 1.98"/>
      </geometry>
    </collision>
  </link>
  <link name="laser_horiz">
    <visual>
      <material name="black"/>
      <geometry>
        <cylinder length="0.072" radius="0.052"/>
      </geometry>
    </visual>
    <collision>
      <geometry>
        <cylinder length="0.072" radius="0.052"/>
      </geometry>
    </collision>
  </link>
  <joint name="base2laser_horiz" type="fixed">
    <parent link="base"/>
    <child link="laser_horiz"/>
    <origin rpy="-0.00121 0.11465 -0.001530" xyz="0.2325 0.0001 1.9201"/>
  </joint>
  <link name="laser_vert_top_right">
    <visual>
      <geometry>
        <box size=".062 .062 .087"/>
      </geometry>
      <material name="black"/>
    </visual>
    <collision>
      <geometry>
        <box size=".062 .062 .087"/>
      </geometry>
    </collision>
  </link>
  <joint name="base2laser_vert_top_right" type="fixed">
    <parent link="base"/>
    <child link="laser_vert_top_right"/>
    <origin rpy="-1.176 0.6313 -1.9377" xyz="0.2978 -0.1450 1.8451"/>
  </joint>
  <link name="laser_vert_top_left">
    <visual>
      <geometry>
        <box size=".062 .062 .087"/>
      </geometry>
      <material name="black"/>
    </visual>
    <collision>
      <geometry>
        <box size=".062 .062 .087"/>
      </geometry>
    </collision>
  </link>
  <joint name="base2laser_vert_top_left" type="fixed">
    <parent link="base"/>
    <child link="laser_vert_top_left"/>
    <origin rpy="1.178 0.6198 1.9560" xyz="0.2997 0.1531 1.8443"/>
  </joint>
  <link name="laser_vert_bottom">
    <visual>
      <geometry>
        <box size=".062 .062 .087"/>
      </geometry>
      <material name="black"/>
    </visual>
    <collision>
      <geometry>
        <box size=".062 .062 .087"/>
      </geometry>
    </collision>
  </link>
  <joint name="base2laser_vert_bottom" type="fixed">
    <parent link="base"/>
    <child link="laser_vert_bottom"/>
    <origin rpy="3.1355 -1.3045 0.0025" xyz="0.3158 -0.0021 .51"/>
  </joint>
  <link name="wheel_right">
    <visual>
      <geometry>
        <cylinder length=".05" radius="0.2"/>
      </geometry>
      <material name="black"/>
    </visual>
    <collision>
      <geometry>
        <cylinder length=".05" radius="0.2"/>
      </geometry>
    </collision>
  </link>
  <joint name="base2wheel_right" type="continuous">
    <parent link="base"/>
    <child link="wheel_right"/>
    <origin rpy="-1.5707 0.0 0.0" xyz="-0.1 -0.4 .2"/>
    <axis xyz="0 1 0"/>
    <limit effort=".1" velocity="99"/>
  </joint>
  <link name="wheel_left">
    <visual>
      <geometry>
        <cylinder length=".05" radius="0.2"/>
      </geometry>
      <material name="black"/>
    </visual>
    <collision>
      <geometry>
        <cylinder length=".05" radius="0.2"/>
      </geometry>
    </collision>
  </link>
  <joint name="base2wheel_left" type="continuous">
    <parent link="base"/>
    <child link="wheel_left"/>
    <origin rpy="-1.5707 0.0 0.0" xyz="-0.1 0.4 .2"/>
    <axis xyz="0 1 0"/>
    <limit effort=".1" velocity="99"/>
  </joint>
  <link name="wheel_front_right">
    <visual>
      <geometry>
        <cylinder length=".05" radius="0.15"/>
      </geometry>
      <material name="black"/>
    </visual>
    <collision>
      <geometry>
        <cylinder length=".05" radius="0.15"/>
      </geometry>
    </collision>
  </link>
  <joint name="base2wheel_front_right" type="continuous">
    <parent link="base"/>
    <child link="wheel_front_right"/>
    <origin rpy="-1.5707 0.0 0.0" xyz="0.5 -0.05 .15"/>
    <axis xyz="0 1 0"/>
    <limit effort=".1" velocity="99"/>
  </joint>
  <link name="wheel_front_left">
    <visual>
      <geometry>
        <cylinder length=".05" radius="0.15"/>
      </geometry>
      <material name="black"/>
    </visual>
    <collision>
      <geometry>
        <cylinder length=".05" radius="0.15"/>
      </geometry>
    </collision>
  </link>
  <joint name="base2wheel_front_left" type="continuous">
    <parent link="base"/>
    <child link="wheel_front_left"/>
    <origin rpy="-1.5707 0.0 0.0" xyz="0.5 0.05 .15"/>
    <axis xyz="0 1 0"/>
    <limit effort=".1" velocity="99"/>
  </joint>
</robot>

